Workbook

Sheet Raw Data
A1: Raw Data — Full committed NAV history used by the live engine to calibrate mu/sigma
A2: Source: data/processed/nav_panel.parquet, replicated via load_nav_returns() -> get_daily_nav() -> build_price_panel() -> log_returns() (backend/app/data/sec_client.py, backend/app/data/returns.py). Funds: M0209_2548 (K-SET50), M0337_2550 (K-MONEY). Date range = full intersection of both funds' reported nav_date history after gap-tolerant forward-fill and dropna(), 2015-01-05 through 2026-07-31 (2702 daily observations, 2701 daily log returns).
A3: IMPORTANT DEVIATION FROM BRIEF: the brief's Step 1 suggested a simple return =NAV_t/NAV_(t-1)-1. The live engine (returns.py::log_returns) actually computes DAILY LOG RETURNS =LN(NAV_t/NAV_(t-1)), and estimate_mu_sigma()/correlation_and_returns_table() operate on that log-return series, not simple returns. This sheet therefore uses LOG returns so that every downstream bit-exact formula in this workbook matches the engine's actual input series. A simple-return column is also provided (labeled) for reference/plausibility only.
A4: GAP-FILL NOTE (candidate CLAUDE.md landmine violation, worth Task 5's attention): 3 isolated dates in this 2702-row panel have a missing NAV for ONE of the two funds in the underlying parquet cache and are forward-filled by build_price_panel() (returns.py) as normal single-day reporting-calendar noise, exactly replicated here so this workbook matches what the live engine actually computed: 2015-04-02 (M0337_2550/MONEY missing, SET50 present), 2015-05-28 (M0209_2548/SET50 missing, MONEY present), 2021-01-18 (SET50 missing, MONEY present) — see rows 68, 101, and 1465 below. This is NOT an unnoticed data error in this workbook; it is a faithful reproduction of the engine's forward-fill behavior. However, CLAUDE.md's landmine list states 'NAV gaps are hard errors. Never forward-fill or interpolate across a gap' — build_price_panel()'s own MAX_TOLERATED_GAP_RUN=5 logic treats a lone missing day as tolerable calendar noise (not a genuine gap) and forward-fills it, which is a documented design choice inside returns.py itself, but is in tension with the landmine's blanket 'never forward-fill' wording. Flagging this as a discrepancy worth Task 5's attention re: whether the landmine text needs to be qualified, or whether single-day forward-fill should also be disallowed.
A5: Date | B5: NAV_SET50 (M0209_2548) | C5: NAV_MONEY (M0337_2550) | D5: LogReturn_SET50 | E5: LogReturn_MONEY | F5: SimpleReturn_SET50 (ref only) | G5: SimpleReturn_MONEY (ref only)
A6: 2015-01-05 | B6: 28.381 | C6: 11.6042
A7: 2015-01-06 | B7: 28.1817 | C7: 11.6049 | D7: =LN(B7/B6) -> -0.0070470761 | E7: =LN(C7/C6) -> 6.0321167e-05 | F7: =B7/B6-1 -> -0.0070223037 | G7: =C7/C6-1 -> 6.0322987e-05
A8: 2015-01-07 | B8: 28.6708 | C8: 11.6057 | D8: =LN(B8/B7) -> 0.017206352 | E8: =LN(C8/C7) -> 6.8934022e-05 | F8: =B8/B7-1 -> 0.017355234 | G8: =C8/C7-1 -> 6.8936398e-05
A9: 2015-01-08 | B9: 29.1099 | C9: 11.6063 | D9: =LN(B9/B8) -> 0.015199139 | E9: =LN(C9/C8) -> 5.1697398e-05 | F9: =B9/B8-1 -> 0.015315234 | G9: =C9/C8-1 -> 5.1698734e-05
A10: 2015-01-09 | B10: 29.1701 | C10: 11.6068 | D10: =LN(B10/B9) -> 0.0020658895 | E10: =LN(C10/C9) -> 4.3079123e-05 | F10: =B10/B9-1 -> 0.002068025 | G10: =C10/C9-1 -> 4.3080051e-05
A11: 2015-01-12 | B11: 29.1393 | C11: 11.6087 | D11: =LN(B11/B10) -> -0.0010564335 | E11: =LN(C11/C10) -> 0.00016368375 | F11: =B11/B10-1 -> -0.0010558757 | G11: =C11/C10-1 -> 0.00016369714
A12: 2015-01-13 | B12: 29.1234 | C12: 11.6094 | D12: =LN(B12/B11) -> -0.00054580376 | E12: =LN(C12/C11) -> 6.0297785e-05 | F12: =B12/B11-1 -> -0.00054565484 | G12: =C12/C11-1 -> 6.0299603e-05
A13: 2015-01-14 | B13: 28.8328 | C13: 11.6099 | D13: =LN(B13/B12) -> -0.010028347 | E13: =LN(C13/C12) -> 4.306762e-05 | F13: =B13/B12-1 -> -0.0099782306 | G13: =C13/C12-1 -> 4.3068548e-05
A14: 2015-01-15 | B14: 28.8158 | C14: 11.6104 | D14: =LN(B14/B13) -> -0.00058978017 | E14: =LN(C14/C13) -> 4.3065766e-05 | F14: =B14/B13-1 -> -0.00058960628 | G14: =C14/C13-1 -> 4.3066693e-05
A15: 2015-01-16 | B15: 28.6944 | C15: 11.611 | D15: =LN(B15/B14) -> -0.004221866 | E15: =LN(C15/C14) -> 5.1676471e-05 | F15: =B15/B14-1 -> -0.0042129665 | G15: =C15/C14-1 -> 5.1677806e-05
A16: 2015-01-19 | B16: 29.0979 | C16: 11.6125 | D16: =LN(B16/B15) -> 0.013964025 | E16: =LN(C16/C15) -> 0.0001291795 | F16: =B16/B15-1 -> 0.014061977 | G16: =C16/C15-1 -> 0.00012918784
A17: 2015-01-20 | B17: 29.069 | C17: 11.6134 | D17: =LN(B17/B16) -> -0.00099369237 | E17: =LN(C17/C16) -> 7.7499688e-05 | F17: =B17/B16-1 -> -0.00099319882 | G17: =C17/C16-1 -> 7.7502691e-05
A18: 2015-01-21 | B18: 29.0659 | C18: 11.6141 | D18: =LN(B18/B17) -> -0.0001066485 | E18: =LN(C18/C17) -> 6.0273383e-05 | F18: =B18/B17-1 -> -0.00010664282 | G18: =C18/C17-1 -> 6.0275199e-05
... A67: 2015-04-01 | B67: 29.0599 | C67: 11.6577 | D67: =LN(B67/B66) -> 0.012096307 | E67: =LN(C67/C66) -> 5.1469453e-05 | F67: =B67/B66-1 -> 0.012169764 | G67: =C67/C66-1 -> 5.1470777e-05
A68: 2015-04-02 | B68: 29.2133 | C68: 11.6577 | D68: =LN(B68/B67) -> 0.005264868 | E68: =LN(C68/C67) -> 0 | F68: =B68/B67-1 -> 0.0052787518 | G68: =C68/C67-1 -> 0 | H68: <-- GAP-FILL: MONEY forward-filled (see row-4 note)
A69: 2015-04-03 | B69: 29.266 | C69: 11.6587 | D69: =LN(B69/B68) -> 0.0018023476 | E69: =LN(C69/C68) -> 8.5776535e-05 | F69: =B69/B68-1 -> 0.0018039728 | G69: =C69/C68-1 -> 8.5780214e-05
A70: 2015-04-07 | B70: 29.5631 | C70: 11.6609 | D70: =LN(B70/B69) -> 0.010100529 | E70: =LN(C70/C69) -> 0.00018868248 | F70: =B70/B69-1 -> 0.010151712 | G70: =C70/C69-1 -> 0.00018870028
A71: 2015-04-08 | B71: 29.4626 | C71: 11.6613 | D71: =LN(B71/B70) -> -0.0034052996 | E71: =LN(C71/C70) -> 3.4302081e-05 | F71: =B71/B70-1 -> -0.0033995082 | G71: =C71/C70-1 -> 3.430267e-05
A72: 2015-04-09 | B72: 29.4815 | C72: 11.6616 | D72: =LN(B72/B71) -> 0.00064128558 | E72: =LN(C72/C71) -> 2.5725789e-05 | F72: =B72/B71-1 -> 0.00064149125 | G72: =C72/C71-1 -> 2.572612e-05
A73: 2015-04-10 | B73: 29.5797 | C73: 11.6622 | D73: =LN(B73/B72) -> 0.0033253673 | E73: =LN(C73/C72) -> 5.1449592e-05 | F73: =B73/B72-1 -> 0.0033309024 | G73: =C73/C72-1 -> 5.1450916e-05
A74: 2015-04-16 | B74: 30.1004 | C74: 11.6656 | D74: =LN(B74/B73) -> 0.017450145 | E74: =LN(C74/C73) -> 0.0002914977 | F74: =B74/B73-1 -> 0.017603289 | G74: =C74/C73-1 -> 0.00029154019
A75: 2015-04-17 | B75: 30.0182 | C75: 11.6662 | D75: =LN(B75/B74) -> -0.0027345963 | E75: =LN(C75/C74) -> 5.1431951e-05 | F75: =B75/B74-1 -> -0.0027308607 | G75: =C75/C74-1 -> 5.1433274e-05
A76: 2015-04-20 | B76: 29.8513 | C76: 11.6679 | D76: =LN(B76/B75) -> -0.0055754744 | E76: =LN(C76/C75) -> 0.0001457095 | F76: =B76/B75-1 -> -0.0055599603 | G76: =C76/C75-1 -> 0.00014572011
A77: 2015-04-21 | B77: 30.0796 | C77: 11.6684 | D77: =LN(B77/B76) -> 0.0076188111 | E77: =LN(C77/C76) -> 4.2851695e-05 | F77: =B77/B76-1 -> 0.0076479081 | G77: =C77/C76-1 -> 4.2852613e-05
A78: 2015-04-22 | B78: 29.6367 | C78: 11.6691 | D78: =LN(B78/B77) -> -0.014833743 | E78: =LN(C78/C77) -> 5.9989288e-05 | F78: =B78/B77-1 -> -0.014724265 | G78: =C78/C77-1 -> 5.9991087e-05
A79: 2015-04-23 | B79: 29.4942 | C79: 11.6698 | D79: =LN(B79/B78) -> -0.0048198244 | E79: =LN(C79/C78) -> 5.9985689e-05 | F79: =B79/B78-1 -> -0.0048082276 | G79: =C79/C78-1 -> 5.9987488e-05
A80: 2015-04-24 | B80: 29.7546 | C80: 11.6703 | D80: =LN(B80/B79) -> 0.008790108 | E80: =LN(C80/C79) -> 4.2844718e-05 | F80: =B80/B79-1 -> 0.0088288545 | G80: =C80/C79-1 -> 4.2845636e-05
... A100: 2015-05-27 | B100: 28.7717 | C100: 11.6886 | D100: =LN(B100/B99) -> 0.001951736 | E100: =LN(C100/C99) -> 4.2777638e-05 | F100: =B100/B99-1 -> 0.0019536419 | G100: =C100/C99-1 -> 4.2778553e-05
A101: 2015-05-28 | B101: 28.7717 | C101: 11.689 | D101: =LN(B101/B100) -> 0 | E101: =LN(C101/C100) -> 3.4220793e-05 | F101: =B101/B100-1 -> 0 | G101: =C101/C100-1 -> 3.4221378e-05 | H101: <-- GAP-FILL: SET50 forward-filled (see row-4 note)
A102: 2015-05-29 | B102: 28.598 | C102: 11.6893 | D102: =LN(B102/B101) -> -0.0060554798 | E102: =LN(C102/C101) -> 2.5664826e-05 | F102: =B102/B101-1 -> -0.0060371824 | G102: =C102/C101-1 -> 2.5665155e-05
A103: 2015-06-02 | B103: 28.2145 | C103: 11.691 | D103: =LN(B103/B102) -> -0.013500755 | E103: =LN(C103/C102) -> 0.00014542157 | F103: =B103/B102-1 -> -0.013410029 | G103: =C103/C102-1 -> 0.00014543215
A104: 2015-06-03 | B104: 28.3223 | C104: 11.6911 | D104: =LN(B104/B103) -> 0.00381345 | E104: =LN(C104/C103) -> 8.5535516e-06 | F104: =B104/B103-1 -> 0.0038207305 | G104: =C104/C103-1 -> 8.5535882e-06
A105: 2015-06-04 | B105: 28.4914 | C105: 11.6914 | D105: =LN(B105/B104) -> 0.0059528071 | E105: =LN(C105/C104) -> 2.5660216e-05 | F105: =B105/B104-1 -> 0.0059705603 | G105: =C105/C104-1 -> 2.5660545e-05
A106: 2015-06-05 | B106: 28.8507 | C106: 11.6917 | D106: =LN(B106/B105) -> 0.012531969 | E106: =LN(C106/C105) -> 2.5659558e-05 | F106: =B106/B105-1 -> 0.012610823 | G106: =C106/C105-1 -> 2.5659887e-05
A107: 2015-06-08 | B107: 28.8234 | C107: 11.6929 | D107: =LN(B107/B106) -> -0.00094669885 | E107: =LN(C107/C106) -> 0.00010263165 | F107: =B107/B106-1 -> -0.00094625087 | G107: =C107/C106-1 -> 0.00010263691
...

Sheet Risk & Correlation
A1: Risk & Correlation — deterministic functions of the historical log-return series (bit-exact target)
A2: Code path: backend/app/engine/results.py::correlation_and_returns_table(returns_df, asset_names, periods_per_year=252), called on the same log-return series in Raw Data columns D/E. All formulas below reference Raw Data cells directly (no pasted Python numbers except the JSON comparison column, which is the ground truth being reconciled against).
A4: Metric | B4: Fund | C4: Excel Formula (native) | D4: Excel Value | E4: JSON Value | F4: Diff | G4: Match (6dp) | H4: Notes
A5: Correlation | B5: SET50 vs MONEY | C5: =CORREL('Raw Data'!D7:D2707,'Raw Data'!E7:E2707) -> 0.20704649 | D5: =CORREL('Raw Data'!D7:D2707,'Raw Data'!E7:E2707) -> 0.20704649 | E5: 0.20704649 | F5: =ROUND(ABS(E5-D5),6) -> 0 | G5: =IF(F5=0,"Y","N") -> Y | H5: CORREL on the full-history log-return series
A6: Expected return (annualized) | B6: SET50 | C6: =AVERAGE('Raw Data'!D7:D2707)*252 -> 0.037540761 | D6: =AVERAGE('Raw Data'!D7:D2707)*252 -> 0.037540761 | E6: 0.037540761 | F6: =ROUND(ABS(E6-D6),6) -> 0 | G6: =IF(F6=0,"Y","N") -> Y | H6: mean(daily log return) * 252
A7: Expected return (annualized) | B7: MONEY | C7: =AVERAGE('Raw Data'!E7:E2707)*252 -> 0.0098107896 | D7: =AVERAGE('Raw Data'!E7:E2707)*252 -> 0.0098107896 | E7: 0.0098107896 | F7: =ROUND(ABS(E7-D7),6) -> 0 | G7: =IF(F7=0,"Y","N") -> Y | H7: mean(daily log return) * 252
A8: Volatility (annualized) | B8: SET50 | C8: =_xlfn.STDEV.S('Raw Data'!D7:D2707)*SQRT(252) -> 0.17290345 | D8: =_xlfn.STDEV.S('Raw Data'!D7:D2707)*SQRT(252) -> 0.17290345 | E8: 0.17290345 | F8: =ROUND(ABS(E8-D8),6) -> 0 | G8: =IF(F8=0,"Y","N") -> Y | H8: sample stdev (ddof=1) of daily log return * sqrt(252)
A9: Volatility (annualized) | B9: MONEY | C9: =_xlfn.STDEV.S('Raw Data'!E7:E2707)*SQRT(252) -> 0.0022617381 | D9: =_xlfn.STDEV.S('Raw Data'!E7:E2707)*SQRT(252) -> 0.0022617381 | E9: 0.0022617381 | F9: =ROUND(ABS(E9-D9),6) -> 0 | G9: =IF(F9=0,"Y","N") -> Y | H9: sample stdev (ddof=1) of daily log return * sqrt(252)
A10: CAGR (from log-return series) | B10: SET50 | C10: =EXP(SUMPRODUCT(LN(1+'Raw Data'!D7:D2707)))^(252/COUNT('Raw Data'!D7:D2707))-1 -> 0.022802778 | D10: =EXP(SUMPRODUCT(LN(1+'Raw Data'!D7:D2707)))^(252/COUNT('Raw Data'!D7:D2707))-1 -> 0.022802778 | E10: 0.022802778 | F10: =ROUND(ABS(E10-D10),6) -> 0 | G10: =IF(F10=0,"Y","N") -> Y | H10: Code literally does PRODUCT(1+log_return) — treats log returns as if simple for the cumulative product step (results.py:179-181). This is what the engine actually computes, so it is what we replicate here for bit-exact reconciliation with the JSON; it is arithmetically NOT a rigorous CAGR (a true CAGR would use PRODUCT(EXP(log_returns)) since prices compound multiplicatively under log returns), but it is not one of the 3 audit-flagged bug candidates so we report it as an additional, previously-uncatalogued minor formula quirk rather than re-litigating it here.
A11: CAGR (from log-return series) | B11: MONEY | C11: =EXP(SUMPRODUCT(LN(1+'Raw Data'!E7:E2707)))^(252/COUNT('Raw Data'!E7:E2707))-1 -> 0.0098563086 | D11: =EXP(SUMPRODUCT(LN(1+'Raw Data'!E7:E2707)))^(252/COUNT('Raw Data'!E7:E2707))-1 -> 0.0098563086 | E11: 0.0098563086 | F11: =ROUND(ABS(E11-D11),6) -> 0 | G11: =IF(F11=0,"Y","N") -> Y | H11: Same PRODUCT(1+log_return) convention as SET50 row above.
A13: Parametric VaR/ES (Gaussian, Jorion closed-form) — portfolio-level cross-check
A14: Note: JSON risk.value_at_risk / risk.expected_shortfall are NOT this parametric figure. Tracing orchestrator.py confirms those two JSON fields come from results.py::compute_var_es(), the HISTORICAL/EMPIRICAL VaR/ES computed on the 2000 simulated ending dollar balances (percentile of simulated outcomes), not the closed-form Gaussian formula below. Since ending balances are a function of the 2000 stochastic GBM paths, that JSON figure falls under the same documented PRNG-reproducibility limitation as the Overview/Distribution sheets (plausibility-only, not bit-exact). The parametric closed-form below is shown as an independent, deterministic cross-check of results.py::parametric_var_es against a Python-computed reference value (not the JSON) — comparing it directly to the JSON's empirical VaR/ES would be an apples-to-oranges mismatch, not a bug.
A16: Weight SET50 | B16: 0.5
A17: Weight MONEY | B17: 0.5
A18: Portfolio mean return (annualized) = w'*mu | B18: =B16*AVERAGE('Raw Data'!D7:D2707)*252+B17*AVERAGE('Raw Data'!E7:E2707)*252 -> 0.023675775
A19: Portfolio variance = w' Sigma w (via COVARIANCE.S) | B19: =B16^2*(_xlfn.STDEV.S('Raw Data'!D7:D2707)*SQRT(252))^2+B17^2*(_xlfn.STDEV.S('Raw Data'!E7:E2707)*SQRT(252))^2+2*B16*B17*_xlfn.COVARIANCE.S('Raw Data'!D7:D2707,'Raw Data'!E7:E2707)*252 -> 0.0075156635
A20: Portfolio volatility (annualized) = sqrt(port variance) | B20: =SQRT(B19) -> 0.086692926
A21: z = _xlfn.NORM.S.INV(0.90) | B21: =_xlfn.NORM.S.INV(0.9) -> 1.2815516
A22: Parametric VaR (90%) = -port_mu + z*port_sd | B22: =-B18+B21*B20 -> 0.08742568
A23: Parametric ES (90%) = -port_mu + [_xlfn.NORM.S.DIST(z,FALSE)/(1-0.90)]*port_sd | B23: =-B18+(_xlfn.NORM.S.DIST(B21,FALSE())/(1-0.9))*B20 -> 0.12846886
A24: Python cross-check VaR (parametric_var_es, independently computed) | B24: 0.08742568 | C24: =ROUND(ABS(B24-B22),6) -> 0 | D24: =IF(C24=0,"Y","N") -> Y
A25: Python cross-check ES (parametric_var_es, independently computed) | B25: 0.12846886 | C25: =ROUND(ABS(B25-B23),6) -> 0 | D25: =IF(C25=0,"Y","N") -> Y

Sheet Growth
A1: Growth — deterministic mu/sigma ingredients feeding the GBM fan chart
A2: The fan_chart itself is generated from 2000 stochastic GBM paths (backend/app/engine/gbm.py) driven by numpy default_rng(seed=42) — Excel cannot replicate that PRNG stream bit-for-bit, so per-path percentile reproduction is out of scope here (see Distribution/Overview sheets for the documented limitation and plausibility checks). What IS deterministic and independently verifiable in Excel is the mu vector and Sigma covariance matrix that estimate_mu_sigma() (returns.py) derives from the historical log-return series, and the portfolio-level w'*mu / w'*Sigma*w reduction of those inputs (statistical.py's GBM branch consumes exactly this mu/Sigma pair). Comparison values below are the Python reference computed directly from estimate_mu_sigma() on the same Raw Data series (not JSON fields — the API does not expose mu/Sigma directly), used as an independent cross-check that the MMULT-based Excel computation is correct.
A4: mu vector (annualized, 2x1)
A5: Fund | B5: mu (Excel formula)
A6: M0209_2548 (SET50) | B6: =AVERAGE('Raw Data'!D7:D2707)*252 -> 0.037540761
A7: M0337_2550 (MONEY) | B7: =AVERAGE('Raw Data'!E7:E2707)*252 -> 0.0098107896
A9: Sigma covariance matrix (annualized, 2x2)
B10: SET50 | C10: MONEY
A11: SET50 | B11: =_xlfn.STDEV.S('Raw Data'!D7:D2707)^2*252 -> 0.029895602 | C11: =_xlfn.COVARIANCE.S('Raw Data'!D7:D2707,'Raw Data'!E7:E2707)*252 -> 8.0968078e-05
A12: MONEY | B12: =_xlfn.COVARIANCE.S('Raw Data'!D7:D2707,'Raw Data'!E7:E2707)*252 -> 8.0968078e-05 | C12: =_xlfn.STDEV.S('Raw Data'!E7:E2707)^2*252 -> 5.1154593e-06
A14: Weights (w)
A15: w_SET50 | B15: 0.5
A16: w_MONEY | B16: 0.5
A18: Portfolio statistics via MMULT
A19: Portfolio mean = w' * mu (=MMULT(TRANSPOSE(w),mu)) | B19: =SUMPRODUCT(B15:B16,B6:B7) -> 0.023675775 | C19: Python cross-check (estimate_mu_sigma, w=[0.5,0.5]) | D19: 0.023675775 | E19: =ROUND(ABS(D19-B19),6) -> 0 | F19: =IF(E19=0,"Y","N") -> Y
A20: Portfolio variance = w' * Sigma * w (via MMULT) | B20: =B15^2*B11+B16^2*C12+2*B15*B16*C11 -> 0.0075156635 | C20: Python cross-check | D20: 0.0075156635 | E20: =ROUND(ABS(D20-B20),6) -> 0 | F20: =IF(E20=0,"Y","N") -> Y
A21: Portfolio volatility = sqrt(portfolio variance) | B21: =SQRT(B20) -> 0.086692926 | C21: Python cross-check | D21: 0.086692926 | E21: =ROUND(ABS(D21-B21),6) -> 0 | F21: =IF(E21=0,"Y","N") -> Y
A23: Plausibility check vs JSON overview.median_cagr / metrics.percentile_table.cagr[50]
A24: GBM 1-year expected log-return drift ~ port_mu - 0.5*port_variance (risk-neutral-of-noise center; the median of many compounded years converges near this under GBM). Reported here as a STOCHASTIC-PLAUSIBILITY check only (not bit-exact) since the JSON's cagr[50] is the median of 2000 simulated paths, subject to Monte Carlo sampling noise.
A25: Expected GBM drift (5yr horizon, port_mu - 0.5*port_var) | B25: =B19-0.5*B20 -> 0.019917943
A26: JSON metrics.percentile_table.cagr[50] (median of 2000 simulated paths) | B26: 0.0024559726
A27: JSON overview.median_cagr (should equal cagr[50] above) | B27: 0.0024559726
A28: Diff (drift proxy vs JSON median) — expected to be within one simulation-noise band, not exact | B28: =ROUND(ABS(B25-B26),6) -> 0.017462
A29: Within plausible band? (|diff| < 0.03, i.e. within a few pct-pts of annual vol) | B29: =IF(B28<0.03,"Y - plausible","N - investigate") -> Y - plausible

Sheet Overview
A1: Overview — closed-form portfolio statistics vs. percentile_table / overview block
A2: Per Task 4 brief Step 2: reconcile the annualized mean/vol of the historical window feeding GBM's mu/sigma against what metrics.percentile_table implies. Deterministic aggregate formulas (mu, sigma per fund) are bit-exact to 6dp (cross-checked against Python, see Risk & Correlation / Growth sheets which contain the authoritative bit-exact comparisons). The percentile BAND values (10/25/50/75/90) below are functions of 2000 stochastic GBM paths and are PLAUSIBILITY-CHECKED ONLY, per the documented PRNG-reproducibility limitation — Excel cannot replicate numpy's default_rng(seed=42) stream.
A4: Run overview (from JSON, hardcoded ground truth)
A5: n_paths | B5: 2000
A6: survived_count | B6: 2000
A7: survival_rate | B7: 1
A8: median_ending_balance | B8: 1012340.3
A9: median_cagr | B9: 0.0024559726
A11: Monotonicity check (plausibility): ending_balance percentile band strictly increasing
A12: Percentile | B12: ending_balance | C12: cagr | D12: twrr_nominal | E12: annual_mean_return | F12: annualized_volatility
A13: 10 | B13: 774016.82 | C13: -0.049942087 | D13: -0.049942087 | E13: -0.047208933 | F13: 0.040260826
A14: 25 | B14: 873896.49 | C14: -0.026598527 | D14: -0.026598527 | E14: -0.024207752 | F14: 0.054649782
A15: 50 | B15: 1012340.3 | C15: 0.0024559726 | D15: 0.0024559726 | E15: 0.0054055158 | F15: 0.072420665
A16: 75 | B16: 1177776.8 | C16: 0.033267103 | D16: 0.033267103 | E16: 0.036343532 | F16: 0.093396102
A17: 90 | B17: 1339812.2 | C17: 0.060251224 | D17: 0.060251224 | E17: 0.064031291 | F17: 0.11138525
A19: Monotonic increasing in ending_balance (P90>P75>P50>P25>P10)? | B19: =IF(AND(B17>B16,B16>B15,B15>B14,B14>B13),"Y","N") -> Y
A20: Monotonic increasing in cagr (P90>P75>P50>P25>P10)? | B20: =IF(AND(C17>C16,C16>C15,C15>C14,C14>C13),"Y","N") -> Y
A21: twrr_nominal identical to cagr, all percentiles? (TWRR/CAGR conflation bug candidate)
A22: Task 2 audit flagged results.py:33 sets twrr_nominal = cagr verbatim (same array), which is only mathematically correct in the absence of cashflows. This run HAS a real goal (withdrawal years 1-5), so twrr_nominal in this JSON should differ from cagr if TWRR were computed correctly (i.e. cashflow-timing-stripped). Numeric check below confirms whether they are bit-identical in this real run, which would corroborate the audit's bug finding.
A23: P10: cagr - twrr_nominal | B23: =C13-D13 -> 0 | C23: =IF(B23=0,"IDENTICAL (confirms bug)","DIFFERENT") -> IDENTICAL (confirms bug)
A24: P25: cagr - twrr_nominal | B24: =C14-D14 -> 0 | C24: =IF(B24=0,"IDENTICAL (confirms bug)","DIFFERENT") -> IDENTICAL (confirms bug)
A25: P50: cagr - twrr_nominal | B25: =C15-D15 -> 0 | C25: =IF(B25=0,"IDENTICAL (confirms bug)","DIFFERENT") -> IDENTICAL (confirms bug)
A26: P75: cagr - twrr_nominal | B26: =C16-D16 -> 0 | C26: =IF(B26=0,"IDENTICAL (confirms bug)","DIFFERENT") -> IDENTICAL (confirms bug)
A27: P90: cagr - twrr_nominal | B27: =C17-D17 -> 0 | C27: =IF(B27=0,"IDENTICAL (confirms bug)","DIFFERENT") -> IDENTICAL (confirms bug)
A29: NOTE: cagr/twrr_nominal are computed in results.py::percentile_table() on `paths` (normalized balance ratio, post-cashflow when a goal is configured). Since this run's `paths` array already has the withdrawal cashflow applied (orchestrator.py passes normalized_paths = dollar_paths / initial_amount, where dollar_paths is apply_named_goals()'s output), the identical-values result above is EXPECTED given the current code (both fields read the exact same underlying `cagr` array — see results.py line 33 `twrr_nominal = cagr`), and is exactly the bug the Task 2 audit flagged: a correctly-computed TWRR would strip the cashflow-timing effect and would NOT equal this cashflow-inclusive CAGR figure whenever a goal/cashflow is present, as it is here.

Sheet Distribution
A1: Distribution — monotonicity checks on stochastic-path-derived risk outputs
A2: risk.expected_return_by_horizon and risk.annual_return_probability (and the 2000-length ending_balance_histogram / max_drawdown_histogram arrays) are functions of the SAME mu/sigma/n_paths/seed as the fan chart — exact percentile reproduction requires numpy's default_rng(seed=42) PRNG stream, which Excel cannot replicate deterministically. KNOWN, DOCUMENTED LIMITATION: this sheet does not attempt bit-exact reproduction of those percentile values. Instead it verifies two properties directly on the JSON-exported numbers via native Excel formulas: (a) monotonicity of the percentile band (P90>P75>P50>P25>P10) for each horizon, and (b) monotonically DECREASING probability as the return threshold rises, for each fixed horizon.
A4: (a) expected_return_by_horizon — percentile-band monotonicity
A5: Horizon (yrs) | B5: P10 | C5: P25 | D5: P50 | E5: P75 | F5: P90 | G5: Monotonic Increasing?
A6: 1 | B6: -0.086640231 | C6: -0.043789311 | D6: 0.014970938 | E6: 0.077629817 | F6: 0.13875246 | G6: =IF(AND(F6>E6,E6>D6,D6>C6,C6>B6),"Y","N") -> Y
A7: 3 | B7: -0.058608358 | C7: -0.032203863 | D7: 0.003232945 | E7: 0.042848179 | F7: 0.078962651 | G7: =IF(AND(F7>E7,E7>D7,D7>C7,C7>B7),"Y","N") -> Y
A8: 5 | B8: -0.049942087 | C8: -0.026598527 | D8: 0.0024559726 | E8: 0.033267103 | F8: 0.060251224 | G8: =IF(AND(F8>E8,E8>D8,D8>C8,C8>B8),"Y","N") -> Y
A10: (b) annual_return_probability — decreasing in threshold, per horizon
A11: Threshold | B11: Horizon 1yr | C11: Horizon 3yr | D11: Horizon 5yr
A12: >= 0.00% | B12: 0.568 | C12: 0.516 | D12: 0.52
A13: >= 2.50% | B13: 0.465 | C13: 0.3575 | D13: 0.304
A14: >= 5.00% | B14: 0.353 | C14: 0.2135 | D14: 0.1465
A15: >= 7.50% | B15: 0.258 | C15: 0.1155 | D15: 0.06
A16: >= 10.00% | B16: 0.1875 | C16: 0.057 | D16: 0.0235
A17: >= 12.50% | B17: 0.1275 | C17: 0.0225 | D17: 0.006
A19: Horizon 1yr: strictly decreasing as threshold rises? | B19: =IF(AND(B13<B12,B14<B13,B15<B14,B16<B15,B17<B16),"Y","N") -> Y
A20: Horizon 3yr: strictly decreasing as threshold rises? | B20: =IF(AND(C13<C12,C14<C13,C15<C14,C16<C15,C17<C16),"Y","N") -> Y
A21: Horizon 5yr: strictly decreasing as threshold rises? | B21: =IF(AND(D13<D12,D14<D13,D15<D14,D16<D15,D17<D16),"Y","N") -> Y
A23: Note: probability of exceeding a HIGHER return threshold should be lower or equal for a fixed horizon; a strict AND-based check flags any inversion for manual review even though minor ties/plateaus at extreme thresholds are not necessarily bugs.

Sheet Metrics
A1: Metrics — Sharpe/Sortino/Withdrawal-Rate formula validation on one illustrative 5-year path
A2: Per brief Step 5: exact percentile-of-2000-paths reproduction is out of scope (documented limitation, see Distribution sheet). Instead this sheet hand-traces the FORMULAS themselves — Sharpe, Sortino, safe withdrawal rate, perpetual withdrawal rate — against one concrete illustrative 5-year annual return path (simulation_period_years=5, matching this run's config), fully worked in native Excel formulas, cross-referencing Task 2 audit's two flagged bug candidates: the Sharpe/Sortino numerator (per-path geometric CAGR) vs. denominator (arithmetic per-period std) basis mismatch.
A4: Illustrative path — 5 annual returns (arbitrary but realistic, chosen by us for this hand-trace, NOT from the simulation)
A5: Year 1 | B5: Year 2 | C5: Year 3 | D5: Year 4 | E5: Year 5
A6: 0.08 | B6: -0.05 | C6: 0.12 | D6: 0.03 | E6: -0.02
A8: Growth factors (1+r)
A9: =1+A6 -> 1.08 | B9: =1+B6 -> 0.95 | C9: =1+C6 -> 1.12 | D9: =1+D6 -> 1.03 | E9: =1+E6 -> 0.98
A11: Per-path CAGR (code's numerator) = PRODUCT(growth factors)^(1/5) - 1 | B11: =PRODUCT(A9:E9)^(1/5)-1 -> 0.030115061
A12: Arithmetic mean annual return (textbook numerator) = AVERAGE(returns) | B12: =AVERAGE(A6:E6) -> 0.032
A13: Volatility (sample stdev of the 5 annual returns) = _xlfn.STDEV.S(returns) | B13: =_xlfn.STDEV.S(A6:E6) -> 0.069785385
A14: Downside deviation = SQRT(SUMPRODUCT((returns<0)*returns^2)/COUNT(returns)) | B14: =SQRT(SUMPRODUCT((A6:E6<0)*A6:E6^2)/COUNT(A6:E6)) -> 0.024083189
A16: Risk-free rate assumption | B16: 0
A18: Sharpe — code's version (CAGR numerator / std denominator)
A19: Formula: (CAGR - rf) / Volatility | B19: =(B11-B16)/B13 -> 0.43153822
A20: Sharpe — textbook same-basis version = (ArithmeticMean - rf) / Volatility | B20: =(B12-B16)/B13 -> 0.45854873
A21: Absolute difference (code vs. textbook Sharpe) | B21: =ABS(B19-B20) -> 0.027010517
A22: Relative difference (% of textbook value) | B22: =IFERROR(ABS(B19-B20)/ABS(B20),"n/a") -> 0.058904354
A24: Sortino — code's version (CAGR numerator / downside-dev denominator)
A25: Formula: (CAGR - rf) / Downside Deviation | B25: =(B11-B16)/B14 -> 1.2504598
A26: Sortino — textbook same-basis version = (ArithmeticMean - rf) / Downside Deviation | B26: =(B12-B16)/B14 -> 1.3287277
A27: Absolute difference (code vs. textbook Sortino) | B27: =ABS(B25-B26) -> 0.078267845
A28: Relative difference (% of textbook value) | B28: =IFERROR(ABS(B25-B26)/ABS(B26),"n/a") -> 0.058904354
A29: CONCLUSION: CAGR (geometric) is systematically below the arithmetic mean whenever returns are volatile (Jensen's gap = ~0.5*variance), so the code's Sharpe/Sortino numerator is biased LOW relative to a textbook same-basis ratio built from the SAME return series' arithmetic mean. On this illustrative path the relative difference shown above quantifies the size of that bias for a mid-volatility 5-year annual path -- confirming the Task 2 audit's basis-mismatch finding is numerically material, not just a theoretical nuance.
A31: Safe withdrawal rate — manual bisection on the SAME illustrative path
A32: Code (results.py::withdrawal_rates_by_percentile): finds constant per-period withdrawal rate (fraction of the path's $1 normalized starting balance) such that balance = MAX(balance*g - rate, 0) for each of the 5 growth factors g, and the balance hits exactly 0 by year 5 (brentq root-find). We replicate this with a manual bisection table: guess a rate, roll forward the 5-period balance, check the sign of the terminal balance, narrow the bracket, repeat.
A33: Iter | B33: Low | C33: High | D33: Guess rate | E33: Bal Y1 | F33: Bal Y2 | G33: Bal Y3 | H33: Bal Y4 | I33: Bal Y5 (terminal)
A34: 1 | B34: 0 | C34: 1 | D34: =(B34+C34)/2 -> 0.5 | E34: =MAX(1*A9-D34,0) -> 0.58 | F34: =MAX(E34*B9-D34,0) -> 0.051 | G34: =MAX(F34*C9-D34,0) -> 0 | H34: =MAX(G34*D9-D34,0) -> 0 | I34: =MAX(H34*E9-D34,0) -> 0
A35: 2 | B35: =IF(I34>0,D34,B34) -> 0 | C35: =IF(I34>0,C34,D34) -> 0.5 | D35: =(B35+C35)/2 -> 0.25 | E35: =MAX(1*A9-D35,0) -> 0.83 | F35: =MAX(E35*B9-D35,0) -> 0.5385 | G35: =MAX(F35*C9-D35,0) -> 0.35312 | H35: =MAX(G35*D9-D35,0) -> 0.1137136 | I35: =MAX(H35*E9-D35,0) -> 0
A36: 3 | B36: =IF(I35>0,D35,B35) -> 0 | C36: =IF(I35>0,C35,D35) -> 0.25 | D36: =(B36+C36)/2 -> 0.125 | E36: =MAX(1*A9-D36,0) -> 0.955 | F36: =MAX(E36*B9-D36,0) -> 0.78225 | G36: =MAX(F36*C9-D36,0) -> 0.75112 | H36: =MAX(G36*D9-D36,0) -> 0.6486536 | I36: =MAX(H36*E9-D36,0) -> 0.51068053
A37: 4 | B37: =IF(I36>0,D36,B36) -> 0.125 | C37: =IF(I36>0,C36,D36) -> 0.25 | D37: =(B37+C37)/2 -> 0.1875 | E37: =MAX(1*A9-D37,0) -> 0.8925 | F37: =MAX(E37*B9-D37,0) -> 0.660375 | G37: =MAX(F37*C9-D37,0) -> 0.55212 | H37: =MAX(G37*D9-D37,0) -> 0.3811836 | I37: =MAX(H37*E9-D37,0) -> 0.18605993
A38: 5 | B38: =IF(I37>0,D37,B37) -> 0.1875 | C38: =IF(I37>0,C37,D37) -> 0.25 | D38: =(B38+C38)/2 -> 0.21875 | E38: =MAX(1*A9-D38,0) -> 0.86125 | F38: =MAX(E38*B9-D38,0) -> 0.5994375 | G38: =MAX(F38*C9-D38,0) -> 0.45262 | H38: =MAX(G38*D9-D38,0) -> 0.2474486 | I38: =MAX(H38*E9-D38,0) -> 0.023749628
A39: 6 | B39: =IF(I38>0,D38,B38) -> 0.21875 | C39: =IF(I38>0,C38,D38) -> 0.25 | D39: =(B39+C39)/2 -> 0.234375 | E39: =MAX(1*A9-D39,0) -> 0.845625 | F39: =MAX(E39*B9-D39,0) -> 0.56896875 | G39: =MAX(F39*C9-D39,0) -> 0.40287 | H39: =MAX(G39*D9-D39,0) -> 0.1805811 | I39: =MAX(H39*E9-D39,0) -> 0
A40: 7 | B40: =IF(I39>0,D39,B39) -> 0.21875 | C40: =IF(I39>0,C39,D39) -> 0.234375 | D40: =(B40+C40)/2 -> 0.2265625 | E40: =MAX(1*A9-D40,0) -> 0.8534375 | F40: =MAX(E40*B9-D40,0) -> 0.58420313 | G40: =MAX(F40*C9-D40,0) -> 0.427745 | H40: =MAX(G40*D9-D40,0) -> 0.21401485 | I40: =MAX(H40*E9-D40,0) -> 0
A41: 8 | B41: =IF(I40>0,D40,B40) -> 0.21875 | C41: =IF(I40>0,C40,D40) -> 0.2265625 | D41: =(B41+C41)/2 -> 0.22265625 | E41: =MAX(1*A9-D41,0) -> 0.85734375 | F41: =MAX(E41*B9-D41,0) -> 0.59182031 | G41: =MAX(F41*C9-D41,0) -> 0.4401825 | H41: =MAX(G41*D9-D41,0) -> 0.23073172 | I41: =MAX(H41*E9-D41,0) -> 0.0034608405
A42: 9 | B42: =IF(I41>0,D41,B41) -> 0.22265625 | C42: =IF(I41>0,C41,D41) -> 0.2265625 | D42: =(B42+C42)/2 -> 0.22460938 | E42: =MAX(1*A9-D42,0) -> 0.85539062 | F42: =MAX(E42*B9-D42,0) -> 0.58801172 | G42: =MAX(F42*C9-D42,0) -> 0.43396375 | H42: =MAX(G42*D9-D42,0) -> 0.22237329 | I42: =MAX(H42*E9-D42,0) -> 0
A43: 10 | B43: =IF(I42>0,D42,B42) -> 0.22265625 | C43: =IF(I42>0,C42,D42) -> 0.22460938 | D43: =(B43+C43)/2 -> 0.22363281 | E43: =MAX(1*A9-D43,0) -> 0.85636719 | F43: =MAX(E43*B9-D43,0) -> 0.58991602 | G43: =MAX(F43*C9-D43,0) -> 0.43707313 | H43: =MAX(G43*D9-D43,0) -> 0.22655251 | I43: =MAX(H43*E9-D43,0) -> 0
A44: 11 | B44: =IF(I43>0,D43,B43) -> 0.22265625 | C44: =IF(I43>0,C43,D43) -> 0.22363281 | D44: =(B44+C44)/2 -> 0.22314453 | E44: =MAX(1*A9-D44,0) -> 0.85685547 | F44: =MAX(E44*B9-D44,0) -> 0.59086816 | G44: =MAX(F44*C9-D44,0) -> 0.43862781 | H44: =MAX(G44*D9-D44,0) -> 0.22864212 | I44: =MAX(H44*E9-D44,0) -> 0.00092474206
A45: 12 | B45: =IF(I44>0,D44,B44) -> 0.22314453 | C45: =IF(I44>0,C44,D44) -> 0.22363281 | D45: =(B45+C45)/2 -> 0.22338867 | E45: =MAX(1*A9-D45,0) -> 0.85661133 | F45: =MAX(E45*B9-D45,0) -> 0.59039209 | G45: =MAX(F45*C9-D45,0) -> 0.43785047 | H45: =MAX(G45*D9-D45,0) -> 0.22759731 | I45: =MAX(H45*E9-D45,0) -> 0
A46: 13 | B46: =IF(I45>0,D45,B45) -> 0.22314453 | C46: =IF(I45>0,C45,D45) -> 0.22338867 | D46: =(B46+C46)/2 -> 0.2232666 | E46: =MAX(1*A9-D46,0) -> 0.8567334 | F46: =MAX(E46*B9-D46,0) -> 0.59063013 | G46: =MAX(F46*C9-D46,0) -> 0.43823914 | H46: =MAX(G46*D9-D46,0) -> 0.22811971 | I46: =MAX(H46*E9-D46,0) -> 0.00029071745
A47: 14 | B47: =IF(I46>0,D46,B46) -> 0.2232666 | C47: =IF(I46>0,C46,D46) -> 0.22338867 | D47: =(B47+C47)/2 -> 0.22332764 | E47: =MAX(1*A9-D47,0) -> 0.85667236 | F47: =MAX(E47*B9-D47,0) -> 0.59051111 | G47: =MAX(F47*C9-D47,0) -> 0.4380448 | H47: =MAX(G47*D9-D47,0) -> 0.22785851 | I47: =MAX(H47*E9-D47,0) -> 0
...

Sheet Goals & Cashflows
A1: Goals & Cashflows — MANDATORY (run has a real goal: $20,000/yr inflation-adjusted withdrawal, yrs 1-5)
A2: Code path: backend/app/engine/goals.py::apply_named_goals / _inflation_factors. Formula: Balance_(t+1) = MAX(Balance_t*(1+R_t) +/- CF_t, 0), and for an inflation-adjusted withdrawal, the real $20,000 target grows nominally by the cumulative inflation factor I_t = PRODUCT(1+inflation_draws up to year t) before being subtracted: nominal_CF_t = -20000 * I_t. goals.summary.success_rate=1.0 is a function of the full 2000-path Monte Carlo (whether each simulated path sustains the withdrawal without hitting 0) and is therefore PLAUSIBILITY-ONLY per the documented PRNG limitation; the cashflow SCHEDULE itself (nominal vs present-dollar reconciliation) is deterministic given the run's median/reported inflation path and is bit-exact checkable below.
A4: Goal config (from run_config.goals[0], hardcoded)
A5: purpose | B5: Retirement withdrawal
A6: is_withdrawal | B6: =TRUE() -> TRUE
A7: amount | B7: 20000
A8: inflation_adjusted | B8: =TRUE() -> TRUE
A9: frequency | B9: annually
A10: starts_year | B10: 1
A11: ends_year | B11: 5
A13: Cell-by-cell 5-period cashflow reconciliation
A14: Year | B14: cashflows_nominal (JSON) | C14: cashflows_present_dollar (JSON) | D14: Implied cumulative inflation factor = nominal/-20000 | E14: Reconstructed present-dollar = nominal / inflation factor | F14: Diff vs -20000 target | G14: Match (6dp)
A15: 0 | B15: 0 | C15: 0 | D15: n/a (year 0, no withdrawal — goal starts_year=1) | E15: n/a | F15: n/a | G15: n/a
A16: 1 | B16: -21212.121 | C16: -20000 | D16: =IF(B16=0,"n/a",B16/-20000) -> 1.0606061 | E16: =IF(B16=0,"n/a",B16/D16) -> -20000 | F16: =ROUND(ABS(-20000-E16),6) -> 0 | G16: =IF(F16=0,"Y","N") -> Y
A17: 2 | B17: -21832.699 | C17: -20000 | D17: =IF(B17=0,"n/a",B17/-20000) -> 1.091635 | E17: =IF(B17=0,"n/a",B17/D17) -> -20000 | F17: =ROUND(ABS(-20000-E17),6) -> 0 | G17: =IF(F17=0,"Y","N") -> Y
A18: 3 | B18: -22491.157 | C18: -20000 | D18: =IF(B18=0,"n/a",B18/-20000) -> 1.1245579 | E18: =IF(B18=0,"n/a",B18/D18) -> -20000 | F18: =ROUND(ABS(-20000-E18),6) -> 0 | G18: =IF(F18=0,"Y","N") -> Y
A19: 4 | B19: -23180.486 | C19: -20000 | D19: =IF(B19=0,"n/a",B19/-20000) -> 1.1590243 | E19: =IF(B19=0,"n/a",B19/D19) -> -20000 | F19: =ROUND(ABS(-20000-E19),6) -> 0 | G19: =IF(F19=0,"Y","N") -> Y
A21: This reconciles goals.py's Fisher-style nominal grossing-up: dividing the reported nominal cashflow by its own implied inflation factor must return exactly the configured real amount (-$20,000), by construction of _inflation_factors()/apply_named_goals(). A Match=N would indicate the reported present_dollar array is NOT self-consistent with the reported nominal array and its own implied inflation path -- a real internal-consistency bug, not a stochastic artifact, since this identity must hold exactly regardless of which inflation path realized.
A23: ** CANDIDATE BUG — missing year-5 withdrawal (flagged by task reviewer, requires Task 5 investigation) **
A24: The configured goal has starts_year=1, ends_year=5 (5 withdrawal years, run_config.goals[0] above). goals.cashflows_nominal from the JSON is [0.0, -21212.121378191365, -21832.69940272253, -22491.157017779355, -23180.486085702538] — index 0 is year 0 (before the goal starts, correctly 0.0), but that leaves only indices 1-4 (4 entries) carrying a nonzero withdrawal, each of which the reconciliation table above labels 'Year 1' .. 'Year 4'. A goal spanning years 1 through 5 inclusive should produce 5 nonzero withdrawal entries (years 1,2,3,4,5), not 4 — there is no distinct array element for a 'year 5' withdrawal at all. This is NOT simply a mislabeling of an existing value; the array is one element short of what starts_year=1/ends_year=5 requires. The roll-forward table below intentionally does NOT reuse the year-4 value (-23180.4860857025) as a stand-in for year 5's withdrawal — that would misrepresent a real data gap as data. Task 5 should trace this exact discrepancy into backend/app/engine/goals.py's cashflow-array construction (likely an off-by-one in the starts_year/ends_year -> array-index mapping, or the array is built with length simulation_period_years=5 covering only year-indices 0..4 while the goal's inclusive 1..5 range needs index 5 as well).
A26: Manual 5-period balance roll-forward illustration (1 illustrative path, growth factors from Metrics sheet)
A27: Uses the SAME illustrative 5-year path from the Metrics sheet as growth factors, applying the JSON's actual nominal withdrawal schedule, to hand-trace Balance_(t+1)=MAX(Balance_t*(1+R_t)-CF_t,0) exactly as goals.py::apply_named_goals implements it (illustrative only — real per-path balances from the actual 2000-path run are not individually recoverable from the JSON).
A28: Year | B28: Growth factor (1+R) | C28: Nominal withdrawal (from JSON) | D28: Balance start | E28: Balance after growth | F28: Balance after withdrawal (=MAX(...,0))
A29: 1 | B29: =Metrics!A9 -> 1.08 | C29: 0 | D29: 1000000 | E29: =D29*B29 -> 1080000 | F29: =MAX(E29+C29,0) -> 1080000
A30: 2 | B30: =Metrics!B9 -> 0.95 | C30: -21212.121 | D30: =F29 -> 1080000 | E30: =D30*B30 -> 1026000 | F30: =MAX(E30+C30,0) -> 1004787.9
A31: 3 | B31: =Metrics!C9 -> 1.12 | C31: -21832.699 | D31: =F30 -> 1004787.9 | E31: =D31*B31 -> 1125362.4 | F31: =MAX(E31+C31,0) -> 1103529.7
A32: 4 | B32: =Metrics!D9 -> 1.03 | C32: -22491.157 | D32: =F31 -> 1103529.7 | E32: =D32*B32 -> 1136635.6 | F32: =MAX(E32+C32,0) -> 1114144.5
A33: 5 | B33: =Metrics!E9 -> 0.98 | C33: MISSING FROM JSON — see note above | D33: =F32 -> 1114144.5 | E33: =D33*B33 -> 1091861.6 | F33: N/A — withdrawal amount for year 5 is not present in the JSON response, so this balance cannot be computed
A35: Note: this is an illustrative demonstration of the roll-forward MECHANICS using the real reported nominal withdrawal schedule combined with an arbitrary (not-from-simulation) return path; it validates that the formula in goals.py is correctly reproduced cell-by-cell, not that this specific ending balance matches any single simulated path in the JSON (those individual paths are not exposed in the response — only percentile summaries are).
A37: Success rate (plausibility-only, stochastic)
A38: goals.summary success_rate (JSON, fraction of 2000 paths that never hit 0 while sustaining withdrawals) | B38: 1
A39: Plausible given overview.survival_rate (should be consistent, both are 2000-path Monte Carlo fractions)? | B39: 1
A40: =IF(B38=B39,"Y - consistent","Check - differ") -> Y - consistent

Sheet Summary Tie-Out
A1: Summary Tie-Out — one row per bit-exact-checkable JSON metric
A2: Only metrics that are DETERMINISTIC functions of the historical return series (not of the 2000 stochastic GBM paths) are listed here per the brief's Step 8 scope. Match column: =ROUND(ABS(JSON-Excel),6)=0. All Excel values reference the native-formula cells on their respective sheets (no re-typed numbers). IMPORTANT FRAMING: of the 14 Match=Y/N rows below, 11 are TRUE JSON tie-outs (7 rows in the 'Risk & Correlation'-sourced block + 4 Goals present-dollar rows, JSON value column literally pulls ='Risk & Correlation'!... / ='Goals & Cashflows'!... referencing the JSON-hardcoded cells on those sheets). The remaining 3 rows, labeled 'Growth sheet cross-checks' below, compare an Excel formula against an INDEPENDENT PYTHON REFERENCE VALUE, not a JSON field — the live API response never exposes mu/Sigma directly, so there is no JSON figure to tie those 3 rows out against; they validate the MMULT-based Excel arithmetic only, and are visually separated under their own subheading for that reason.
A4: Metric | B4: JSON value | C4: Excel value | D4: Diff | E4: Match (Y/N) | F4: Notes
A5: Correlation (SET50 vs MONEY) | B5: ='Risk & Correlation'!E5 -> 0.20704649 | C5: ='Risk & Correlation'!D5 -> 0.20704649 | D5: =ROUND(ABS(B5-C5),6) -> 0 | E5: =IF(D5=0,"Y","N") -> Y | F5: See Risk & Correlation sheet for formula + full note
A6: Expected return SET50 | B6: ='Risk & Correlation'!E6 -> 0.037540761 | C6: ='Risk & Correlation'!D6 -> 0.037540761 | D6: =ROUND(ABS(B6-C6),6) -> 0 | E6: =IF(D6=0,"Y","N") -> Y | F6: See Risk & Correlation sheet for formula + full note
A7: Expected return MONEY | B7: ='Risk & Correlation'!E7 -> 0.0098107896 | C7: ='Risk & Correlation'!D7 -> 0.0098107896 | D7: =ROUND(ABS(B7-C7),6) -> 0 | E7: =IF(D7=0,"Y","N") -> Y | F7: See Risk & Correlation sheet for formula + full note
A8: Volatility SET50 | B8: ='Risk & Correlation'!E8 -> 0.17290345 | C8: ='Risk & Correlation'!D8 -> 0.17290345 | D8: =ROUND(ABS(B8-C8),6) -> 0 | E8: =IF(D8=0,"Y","N") -> Y | F8: See Risk & Correlation sheet for formula + full note
A9: Volatility MONEY | B9: ='Risk & Correlation'!E9 -> 0.0022617381 | C9: ='Risk & Correlation'!D9 -> 0.0022617381 | D9: =ROUND(ABS(B9-C9),6) -> 0 | E9: =IF(D9=0,"Y","N") -> Y | F9: See Risk & Correlation sheet for formula + full note
A10: CAGR (log-return basis) SET50 | B10: ='Risk & Correlation'!E10 -> 0.022802778 | C10: ='Risk & Correlation'!D10 -> 0.022802778 | D10: =ROUND(ABS(B10-C10),6) -> 0 | E10: =IF(D10=0,"Y","N") -> Y | F10: See Risk & Correlation sheet for formula + full note
A11: CAGR (log-return basis) MONEY | B11: ='Risk & Correlation'!E11 -> 0.0098563086 | C11: ='Risk & Correlation'!D11 -> 0.0098563086 | D11: =ROUND(ABS(B11-C11),6) -> 0 | E11: =IF(D11=0,"Y","N") -> Y | F11: See Risk & Correlation sheet for formula + full note
A12: Goals cashflows_present_dollar, Year 1 (should equal configured -$20,000) | B12: ='Goals & Cashflows'!C16 -> -20000 | C12: -20000 | D12: =ROUND(ABS(B12-C12),6) -> 0 | E12: =IF(D12=0,"Y","N") -> Y | F12: Deterministic identity check: present-dollar cashflow must equal the goal's configured real amount by construction (Fisher deflation of the nominal series).
A13: Goals cashflows_present_dollar, Year 2 (should equal configured -$20,000) | B13: ='Goals & Cashflows'!C17 -> -20000 | C13: -20000 | D13: =ROUND(ABS(B13-C13),6) -> 0 | E13: =IF(D13=0,"Y","N") -> Y | F13: Deterministic identity check: present-dollar cashflow must equal the goal's configured real amount by construction (Fisher deflation of the nominal series).
A14: Goals cashflows_present_dollar, Year 3 (should equal configured -$20,000) | B14: ='Goals & Cashflows'!C18 -> -20000 | C14: -20000 | D14: =ROUND(ABS(B14-C14),6) -> 0 | E14: =IF(D14=0,"Y","N") -> Y | F14: Deterministic identity check: present-dollar cashflow must equal the goal's configured real amount by construction (Fisher deflation of the nominal series).
A15: Goals cashflows_present_dollar, Year 4 (should equal configured -$20,000) | B15: ='Goals & Cashflows'!C19 -> -20000 | C15: -20000 | D15: =ROUND(ABS(B15-C15),6) -> 0 | E15: =IF(D15=0,"Y","N") -> Y | F15: Deterministic identity check: present-dollar cashflow must equal the goal's configured real amount by construction (Fisher deflation of the nominal series).
A17: Growth sheet cross-checks (Python-independent-reference, not JSON — see Growth sheet for rationale)
A18: Portfolio mean return w'*mu | B18: =Growth!D19 -> 0.023675775 | C18: =Growth!B19 -> 0.023675775 | D18: =ROUND(ABS(B18-C18),6) -> 0 | E18: =IF(D18=0,"Y","N") -> Y | F18: Reference is an independent Python computation of estimate_mu_sigma(), NOT a JSON field (the API does not expose mu/Sigma) — cross-check of the MMULT-based Excel math only.
A19: Portfolio variance w'*Sigma*w | B19: =Growth!D20 -> 0.0075156635 | C19: =Growth!B20 -> 0.0075156635 | D19: =ROUND(ABS(B19-C19),6) -> 0 | E19: =IF(D19=0,"Y","N") -> Y | F19: Reference is an independent Python computation of estimate_mu_sigma(), NOT a JSON field (the API does not expose mu/Sigma) — cross-check of the MMULT-based Excel math only.
A20: Portfolio volatility sqrt(variance) | B20: =Growth!D21 -> 0.086692926 | C20: =Growth!B21 -> 0.086692926 | D20: =ROUND(ABS(B20-C20),6) -> 0 | E20: =IF(D20=0,"Y","N") -> Y | F20: Reference is an independent Python computation of estimate_mu_sigma(), NOT a JSON field (the API does not expose mu/Sigma) — cross-check of the MMULT-based Excel math only.
A22: Real bug candidates flagged (see individual sheets + report for full analysis)
A23: TWRR/CAGR conflation (results.py:33) — see Overview sheet numeric confirmation. Real run has a goal/cashflow, so a correct TWRR should differ from CAGR; JSON shows them bit-identical at every percentile, confirming the Task 2 audit's bug candidate is live in this real run.
A24: Sharpe/Sortino numerator basis mismatch (results.py:126-139) — see Metrics sheet illustrative-path quantification of the CAGR-vs-arithmetic-mean gap and its effect on the ratio.
A25: JSON risk.value_at_risk/expected_shortfall are empirical (compute_var_es on 2000 simulated ending balances), not the parametric closed-form the brief's Step 6 wording suggested comparing against — see Risk & Correlation sheet note. Not a bug, a scope clarification.
A26: MISSING YEAR-5 WITHDRAWAL CASHFLOW (goals.py) — goals.cashflows_nominal from the JSON is [0.0, -21212.121378191365, -21832.69940272253, -22491.157017779355, -23180.486085702538]: index 0 = year 0 (correctly 0.0, goal starts_year=1), but only indices 1-4 carry a nonzero withdrawal (4 entries) for a goal configured starts_year=1/ends_year=5 (5 withdrawal years). There is no distinct array entry for a year-5 withdrawal at all — see Goals & Cashflows sheet's flagged roll-forward row (year 5's withdrawal amount is left explicitly blank/flagged rather than reusing year 4's -23180.4860857025). Candidate real bug in backend/app/engine/goals.py's cashflow-array construction; Task 5 should investigate.
A27: NAV FORWARD-FILL ON 3 GAP DATES (returns.py::build_price_panel) vs. CLAUDE.md landmine 'NAV gaps are hard errors, never forward-fill or interpolate' — 3 isolated dates (2015-04-02, 2015-05-28, 2021-01-18) have a single-fund missing NAV in the underlying parquet cache and are forward-filled as tolerated calendar noise (MAX_TOLERATED_GAP_RUN=5) rather than raising NavGapError. This workbook faithfully reproduces that behavior (see highlighted rows in Raw Data) rather than papering over it, but the landmine's blanket wording doesn't obviously carve out single-day forward-fill as an exception — worth Task 5's attention to confirm whether this is intended or the landmine text needs to be qualified.
